<robot
  name="lnt_urdf_description">
  <link
    name="base_link">
    <inertial>
      <origin
        xyz="0.040643979573491 0.0406419965644875 0.148760063652187"
        rpy="0 0 0" />
      <mass
        value="0.854155845147982" />
      <inertia
        ixx="0.0072097253379719"
        ixy="3.91661557279195E-07"
        ixz="8.32333709729228E-05"
        iyy="0.00710852611283595"
        iyz="-7.71172614028263E-05"
        izz="0.00103326398530037" />
    </inertial>
    <visual>
      <origin
        xyz="0 0 0"
        rpy="0 0 0" />
      <geometry>
        <mesh
          filename="package://lnt_urdf_description/meshes/base_link.STL" />
      </geometry>
      <material
        name="">
        <color
          rgba="0.752941176470588 0.752941176470588 0.752941176470588 1" />
      </material>
    </visual>
    <collision>
      <origin
        xyz="0 0 0"
        rpy="0 0 0" />
      <geometry>
        <mesh
          filename="package://lnt_urdf_description/meshes/base_link.STL" />
      </geometry>
    </collision>
  </link>
  <link
    name="link_1">
    <inertial>
      <origin
        xyz="4.90057691613643E-05 -0.00293063013815038 0.0290827578020298"
        rpy="0 0 0" />
      <mass
        value="0.377267733129056" />
      <inertia
        ixx="0.000641277937131854"
        ixy="-1.1478524551702E-07"
        ixz="5.79330746017939E-07"
        iyy="0.00019199703768203"
        iyz="6.07837956690088E-06"
        izz="0.000630748841506656" />
    </inertial>
    <visual>
      <origin
        xyz="0 0 0"
        rpy="0 0 0" />
      <geometry>
        <mesh
          filename="package://lnt_urdf_description/meshes/link_1.STL" />
      </geometry>
      <material
        name="">
        <color
          rgba="0.752941176470588 0.752941176470588 0.752941176470588 1" />
      </material>
    </visual>
    <collision>
      <origin
        xyz="0 0 0"
        rpy="0 0 0" />
      <geometry>
        <mesh
          filename="package://lnt_urdf_description/meshes/link_1.STL" />
      </geometry>
    </collision>
  </link>
  <joint
    name="joint1"
    type="revolute">
    <origin
      xyz="0.039875 0.040125 0.3045"
      rpy="-3.0787E-17 1.1753E-16 1.5708" />
    <parent
      link="base_link" />
    <child
      link="link_1" />
    <axis
      xyz="0 0 1" />
    <limit
      lower="-3.14"
      upper="3.14"
      effort="0"
      velocity="0" />
  </joint>
  <link
    name="link_2">
    <inertial>
      <origin
        xyz="0.311175688435593 -0.000520999176909009 0.00364100635169962"
        rpy="0 0 0" />
      <mass
        value="0.555909264188641" />
      <inertia
        ixx="0.000771033197074073"
        ixy="-2.35747155363053E-05"
        ixz="3.1553359897087E-05"
        iyy="0.0144365415438456"
        iyz="-1.35189943952058E-06"
        izz="0.0139570184140524" />
    </inertial>
    <visual>
      <origin
        xyz="0 0 0"
        rpy="0 0 0" />
      <geometry>
        <mesh
          filename="package://lnt_urdf_description/meshes/link_2.STL" />
      </geometry>
      <material
        name="">
        <color
          rgba="0.752941176470588 0.752941176470588 0.752941176470588 1" />
      </material>
    </visual>
    <collision>
      <origin
        xyz="0 0 0"
        rpy="0 0 0" />
      <geometry>
        <mesh
          filename="package://lnt_urdf_description/meshes/link_2.STL" />
      </geometry>
    </collision>
  </link>
  <joint
    name="joint2"
    type="revolute">
    <origin
      xyz="0 0 0.0305"
      rpy="-1.5708 0 4.3305E-16" />
    <parent
      link="link_1" />
    <child
      link="link_2" />
    <axis
      xyz="0 0 1" />
    <limit
      lower="0"
      upper="-3.14"
      effort="0"
      velocity="0" />
  </joint>
  <link
    name="link_3">
    <inertial>
      <origin
        xyz="-0.169474131534032 -0.0500512457629598 -0.00170509113305032"
        rpy="0 0 0" />
      <mass
        value="0.292706779888183" />
      <inertia
        ixx="0.000332555030455513"
        ixy="-0.000161514105326486"
        ixz="8.37410047316708E-05"
        iyy="0.00280358448042595"
        iyz="2.44320464003209E-05"
        izz="0.00267450897995474" />
    </inertial>
    <visual>
      <origin
        xyz="0 0 0"
        rpy="0 0 0" />
      <geometry>
        <mesh
          filename="package://lnt_urdf_description/meshes/link_3.STL" />
      </geometry>
      <material
        name="">
        <color
          rgba="0.752941176470588 0.752941176470588 0.752941176470588 1" />
      </material>
    </visual>
    <collision>
      <origin
        xyz="0 0 0"
        rpy="0 0 0" />
      <geometry>
        <mesh
          filename="package://lnt_urdf_description/meshes/link_3.STL" />
      </geometry>
    </collision>
  </link>
  <joint
    name="joint3"
    type="revolute">
    <origin
      xyz="0.43132 -0.0012844 0"
      rpy="-2.3411E-15 -4.0406E-15 1.0617E-29" />
    <parent
      link="link_2" />
    <child
      link="link_3" />
    <axis
      xyz="0 0 1" />
    <limit
      lower="0"
      upper="3.14159"
      effort="0"
      velocity="0" />
  </joint>
  <link
    name="link_4">
    <inertial>
      <origin
        xyz="-7.39902665310987E-05 0.00465167357643108 0.0389281580850401"
        rpy="0 0 0" />
      <mass
        value="0.159649260916991" />
      <inertia
        ixx="0.000133249401429536"
        ixy="-4.75917767767368E-08"
        ixz="-3.08921595105016E-07"
        iyy="5.32131244910627E-05"
        iyz="-1.80050439489608E-06"
        izz="0.000127949156669396" />
    </inertial>
    <visual>
      <origin
        xyz="0 0 0"
        rpy="0 0 0" />
      <geometry>
        <mesh
          filename="package://lnt_urdf_description/meshes/link_4.STL" />
      </geometry>
      <material
        name="">
        <color
          rgba="0.752941176470588 0.752941176470588 0.752941176470588 1" />
      </material>
    </visual>
    <collision>
      <origin
        xyz="0 0 0"
        rpy="0 0 0" />
      <geometry>
        <mesh
          filename="package://lnt_urdf_description/meshes/link_4.STL" />
      </geometry>
    </collision>
  </link>
  <joint
    name="joint4"
    type="revolute">
    <origin
      xyz="-0.2911 -0.05351 0"
      rpy="1.5708 2.6742E-15 -1.5708" />
    <parent
      link="link_3" />
    <child
      link="link_4" />
    <axis
      xyz="0 0 -1" />
    <limit
      lower="-2.09"
      upper="2.09"
      effort="0"
      velocity="0" />
  </joint>
  <link
    name="link_5">
    <inertial>
      <origin
        xyz="-0.0701915459000638 -0.00833031698142439 -0.00103030017205773"
        rpy="0 0 0" />
      <mass
        value="0.215222730814982" />
      <inertia
        ixx="0.000198557406368773"
        ixy="-4.6954389784777E-07"
        ixz="1.75539877526658E-05"
        iyy="0.000280999987740404"
        iyz="1.94581019886887E-06"
        izz="0.000307113755598205" />
    </inertial>
    <visual>
      <origin
        xyz="0 0 0"
        rpy="0 0 0" />
      <geometry>
        <mesh
          filename="package://lnt_urdf_description/meshes/link_5.STL" />
      </geometry>
      <material
        name="">
        <color
          rgba="0.752941176470588 0.752941176470588 0.752941176470588 1" />
      </material>
    </visual>
    <collision>
      <origin
        xyz="0 0 0"
        rpy="0 0 0" />
      <geometry>
        <mesh
          filename="package://lnt_urdf_description/meshes/link_5.STL" />
      </geometry>
    </collision>
  </link>
  <joint
    name="joint5"
    type="revolute">
    <origin
      xyz="0 0 0.041"
      rpy="1.5708 1.5708 0" />
    <parent
      link="link_4" />
    <child
      link="link_5" />
    <axis
      xyz="0 0 1" />
    <limit
      lower="-1.57"
      upper="1.57"
      effort="0"
      velocity="0" />
  </joint>
  <link
    name="link_6">
    <inertial>
      <origin
        xyz="-8.5916E-05 0.0062618 0.040557"
        rpy="0 0 0" />
      <mass
        value="0.1106" />
      <inertia
        ixx="9.9894E-05"
        ixy="-7.5261E-08"
        ixz="-1.3381E-07"
        iyy="4.9526E-05"
        iyz="6.8097E-06"
        izz="9.7012E-05" />
    </inertial>
    <visual>
      <origin
        xyz="0 0 0"
        rpy="0 0 0" />
      <geometry>
        <mesh
          filename="package://lnt_urdf_description/meshes/link_6.STL" />
      </geometry>
      <material
        name="">
        <color
          rgba="0.75294 0.75294 0.75294 1" />
      </material>
    </visual>
    <collision>
      <origin
        xyz="0 0 0"
        rpy="0 0 0" />
      <geometry>
        <mesh
          filename="package://lnt_urdf_description/meshes/link_6.STL" />
      </geometry>
    </collision>
  </link>
  <joint
    name="joint6"
    type="revolute">
    <origin
      xyz="-0.122 0 0"
      rpy="1.5708 -1.1102E-16 -1.5708" />
    <parent
      link="link_5" />
    <child
      link="link_6" />
    <axis
      xyz="0 0 -1" />
    <limit
      lower="-3.14"
      upper="3.14"
      effort="0"
      velocity="0" />
  </joint>
  <link
    name="left_grip_link">
    <inertial>
      <origin
        xyz="0.04463 -0.0018364 0.0066327"
        rpy="0 0 0" />
      <mass
        value="0.018543" />
      <inertia
        ixx="6.2622E-06"
        ixy="1.1538E-06"
        ixz="-1.5186E-06"
        iyy="1.2434E-05"
        iyz="6.7138E-07"
        izz="1.5288E-05" />
    </inertial>
    <visual>
      <origin
        xyz="0 0 0"
        rpy="0 0 0" />
      <geometry>
        <mesh
          filename="package://lnt_urdf_description/meshes/left_grip_link.STL" />
      </geometry>
      <material
        name="">
        <color
          rgba="0.75294 0.75294 0.75294 1" />
      </material>
    </visual>
    <collision>
      <origin
        xyz="0 0 0"
        rpy="0 0 0" />
      <geometry>
        <mesh
          filename="package://lnt_urdf_description/meshes/left_grip_link.STL" />
      </geometry>
    </collision>
  </link>
  <joint
    name="left_grip_joint"
    type="prismatic">
    <origin
      xyz="-0.00038798 -0.0193 0.1357"
      rpy="1.5708 1.5708 0" />
    <parent
      link="link_6" />
    <child
      link="left_grip_link" />
    <axis
      xyz="0 0 1" />
    <limit
      lower="0"
      upper="0"
      effort="0"
      velocity="0" />
  </joint>
  <link
    name="right_grip_link">
    <inertial>
      <origin
        xyz="0.00183644059394827 0.044630390849177 0.00663270264104446"
        rpy="0 0 0" />
      <mass
        value="0.0185428410821074" />
      <inertia
        ixx="1.24340447117038E-05"
        ixy="-1.15375995016126E-06"
        ixz="-6.7137649268847E-07"
        iyy="6.26215242543191E-06"
        iyz="-1.51856815875631E-06"
        izz="1.52881217067195E-05" />
    </inertial>
    <visual>
      <origin
        xyz="0 0 0"
        rpy="0 0 0" />
      <geometry>
        <mesh
          filename="package://lnt_urdf_description/meshes/right_grip_link.STL" />
      </geometry>
      <material
        name="">
        <color
          rgba="0.752941176470588 0.752941176470588 0.752941176470588 1" />
      </material>
    </visual>
    <collision>
      <origin
        xyz="0 0 0"
        rpy="0 0 0" />
      <geometry>
        <mesh
          filename="package://lnt_urdf_description/meshes/right_grip_link.STL" />
      </geometry>
    </collision>
  </link>
  <joint
    name="right_grip_joint"
    type="prismatic">
    <origin
      xyz="0.00038798 0.0423 0.1358"
      rpy="-1.5708 1.1403E-16 -3.1416" />
    <parent
      link="link_6" />
    <child
      link="right_grip_link" />
    <axis
      xyz="0 0 -1" />
    <limit
      lower="0"
      upper="0"
      effort="0"
      velocity="0" />
  </joint>
</robot>
